<!DOCTYPE html>
<html>
<head>
  <title>Раскрутка стека. Исключения в конструкторе и деструкторе</title>
<meta name="viewport" content="width=device-width, initial-scale=1, viewport-fit=cover">
  <meta charset="utf-8">
<style>body{font-family:Helvetica,arial,sans-serif;font-size:14px;line-height:1.6;background-color:#fff;padding:30px;color:#333;max-width:1140px;margin:0 auto}body > :first-child{margin-top:0!important}body > :last-child{margin-bottom:0!important}a{color:#4183C4;text-decoration:none}a.absent{color:#c00}a.anchor{display:block;padding-left:30px;margin-left:-30px;cursor:pointer;position:absolute;top:0;left:0;bottom:0}h1,h2,h3,h4,h5,h6{margin:20px 0 10px;padding:0;font-weight:700;-webkit-font-smoothing:antialiased;cursor:text;position:relative}h2:first-child,h1:first-child,h1:first-child + h2,h3:first-child,h4:first-child,h5:first-child,h6:first-child{margin-top:0;padding-top:0}h1:hover a.anchor,h2:hover a.anchor,h3:hover a.anchor,h4:hover a.anchor,h5:hover a.anchor,h6:hover a.anchor{text-decoration:none}h1 tt,h1 code{font-size:inherit}h2 tt,h2 code{font-size:inherit}h3 tt,h3 code{font-size:inherit}h4 tt,h4 code{font-size:inherit}h5 tt,h5 code{font-size:inherit}h6 tt,h6 code{font-size:inherit}h1{font-size:28px;color:#000}h2{font-size:24px;border-bottom:1px solid #ccc;color:#000}h3{font-size:18px}h4{font-size:16px}h5{font-size:14px}h6{color:#777;font-size:14px}p,blockquote,ul,ol,dl,li,table,pre{margin:15px 0}hr {padding:0;margin-bottom:-8px;height:1px;border:none;background:black}body > h2:first-child{margin-top:0;padding-top:0}body > h1:first-child{margin-top:0;padding-top:0}body > h1:first-child + h2{margin-top:0;padding-top:0}body > h3:first-child,body > h4:first-child,body > h5:first-child,body > h6:first-child{margin-top:0;padding-top:0}a:first-child h1,a:first-child h2,a:first-child h3,a:first-child h4,a:first-child h5,a:first-child h6{margin-top:0;padding-top:0}h1 p,h2 p,h3 p,h4 p,h5 p,h6 p{margin-top:0}li p.first{display:inline-block}ul,ol{padding-left:30px}ul :first-child,ol :first-child{margin-top:0}ul :last-child,ol :last-child{margin-bottom:0}dl{padding:0}dl dt{font-size:14px;font-weight:700;font-style:italic;padding:0;margin:15px 0 5px}dl dt:first-child{padding:0}dl dt > :first-child{margin-top:0}dl dt > :last-child{margin-bottom:0}dl dd{margin:0 0 15px;padding:0 15px}dl dd > :first-child{margin-top:0}dl dd > :last-child{margin-bottom:0}blockquote{border-left:4px solid #ddd;padding:0 15px;color:#777}blockquote > :first-child{margin-top:0}blockquote > :last-child{margin-bottom:0}table{padding:0}table tr{border-top:1px solid #ccc;background-color:#fff;margin:0;padding:0}table tr:nth-child(2n){background-color:#f8f8f8}table tr th{font-weight:700;border:1px solid #ccc;text-align:left;margin:0;padding:6px 13px}table tr td{border:1px solid #ccc;text-align:left;margin:0;padding:6px 13px}table tr th :first-child,table tr td :first-child{margin-top:0}table tr th :last-child,table tr td :last-child{margin-bottom:0}img{max-width:100%}span.frame{display:block;overflow:hidden}span.frame > span{border:1px solid #ddd;display:block;float:left;overflow:hidden;margin:13px 0 0;padding:7px;width:auto}span.frame span img{display:block;float:left}span.frame span span{clear:both;color:#333;display:block;padding:5px 0 0}span.align-center{display:block;overflow:hidden;clear:both}span.align-center > span{display:block;overflow:hidden;margin:13px auto 0;text-align:center}span.align-center span img{margin:0 auto;text-align:center}span.align-right{display:block;overflow:hidden;clear:both}span.align-right > span{display:block;overflow:hidden;margin:13px 0 0;text-align:right}span.align-right span img{margin:0;text-align:right}span.float-left{display:block;margin-right:13px;overflow:hidden;float:left}span.float-left span{margin:13px 0 0}span.float-right{display:block;margin-left:13px;overflow:hidden;float:right}span.float-right > span{display:block;overflow:hidden;margin:13px auto 0;text-align:right}code,tt{margin:0 2px;padding:0 5px;white-space:nowrap;border:1px solid #eaeaea;background-color:#f8f8f8;border-radius:3px}pre code{margin:0;padding:0;white-space:pre;border:none;background:transparent}.highlight pre{background-color:#f8f8f8;border:1px solid #ccc;font-size:13px;line-height:19px;overflow:auto;padding:6px 10px;border-radius:3px}pre{background-color:#f8f8f8;border:1px solid #ccc;font-size:13px;line-height:19px;overflow:auto;padding:6px 10px;border-radius:3px}pre code,pre tt{background-color:transparent;border:none}.slasher{color:#000000}</style></head>
<body>

<h1>Раскрутка стека. Исключения в конструкторе и деструкторе</h1>

<p>В этом уроке вы узнаете, что именно происходит при выбрасывании исключения в программе. А ещё изучите особенности работы исключений в конструкторе и деструкторе объекта.</p>

<h3>Раскрутка стека</h3>

<p>В прошлом уроке вы узнали, что при выполнении выражения <code>throw</code> управление передаётся в ближайший подходящий обработчик исключения. Чтобы проследить, как выбрасывание исключений влияет на жизненный цикл созданных в программе объектов, создадим класс <code>Greeter</code>. Он выводит сообщения в своём конструкторе и деструкторе:</p>

<pre><code class="language-cpp">class Greeter {
public:
    Greeter(const string&amp; name)
        : name_(name)  // Сохраняем name_ внутри
    {
        cout &lt;&lt; &quot;Hello, &quot;s &lt;&lt; name_ &lt;&lt; endl;
    }

    ~Greeter() {
        cout &lt;&lt; &quot;Goodbye, &quot;s &lt;&lt; name_ &lt;&lt; endl;
    }

private:
    string name_;
};

void Test() {
    Greeter a{&quot;Test-A&quot;s};
    Greeter b{&quot;Test-B&quot;s};
    cout &lt;&lt; &quot;Throwing an exception&quot;s &lt;&lt; endl;
    throw runtime_error(&quot;oops&quot;);
}

int main() {
    Greeter greeter_main{&quot;main&quot;s};
    try {
        Greeter outer{&quot;outer&quot;s};

        try {
            Greeter inner{&quot;inner&quot;s};
            Test();
        } catch (const invalid_argument&amp; e) {
            cout &lt;&lt; &quot;invalid_argument: &quot;s &lt;&lt; e.what() &lt;&lt; endl;
        }
        cout &lt;&lt; &quot;This text will not be printed&quot;s &lt;&lt; endl;
    } catch (const runtime_error&amp; e) {
        cout &lt;&lt; &quot;runtime_error: &quot;s &lt;&lt; e.what() &lt;&lt; endl;
    }
    cout &lt;&lt; &quot;------&quot;s &lt;&lt; endl;
}
</code></pre>

<p>Программа выведет:</p>

<pre><code>Hello, main
Hello, outer
Hello, inner
Hello, Test-A
Hello, Test-B
Throwing an exception
Goodbye, Test-B
Goodbye, Test-A
Goodbye, inner
Goodbye, outer
runtime_error: oops
------
Goodbye, main
</code></pre>

<p>При выбрасывании исключения происходит раскрутка стека: программа последовательно покидает вложенные блоки, пока не достигнет начала блока <code>try</code>. Если в текущем блоке <code>try</code> будет найден подходящий блок <code>catch</code>, управление передаётся в него. В противном случае процесс будет продолжаться. Во время раскрутки стека вызываются деструкторы всех локальных переменных каждого блока в порядке, обратном вызову конструкторов.</p>

<p>В нашем случае обработчик исключения, способный поймать <code>runtime_error</code>,  находится во внешнем блоке <code>try</code>. Первыми будут вызваны деструкторы объектов внутри функции <code>Test</code>. Вызваны они будут в порядке, обратном их конструированию: сначала деструктор <code>b</code>, потом <code>a</code>. Затем — деструктор объекта <code>inner</code> из внутреннего блока <code>try</code>, а после — деструктор объекта <code>outer</code> из внешнего блока <code>try</code>. Следом выполнится обработчик пойманного исключения. В конце, перед самым выходом из функции <code>main</code>, произойдёт разрушение переменной <code>greeter_main</code>.</p>

<p>Таким образом, C++ гарантирует вызов деструкторов для всех созданных объектов при выходе из их области видимости, какова бы ни была причина выхода: обычное выполнение программы, возврат из функции по <code>return</code> либо выбрасывание исключения.</p>

<p>Детерминированный механизм вызова деструкторов — одна из сильных сторон C++. Он  упрощает управление ресурсами. Если каждым ресурсом программы владеет некоторый класс, то при выходе из области видимости переменной этого класса гарантированно произойдёт вызов деструктора. Деструктор автоматически освободит ресурс.</p>

<h3>Выбрасывание исключения в конструкторе и деструкторе</h3>

<p>Вы уже знаете, что в C++ жизненный цикл объекта начинается с вызова конструктора. Его основная задача — инициализировать начальное состояние объекта. После окончания работы конструктора инициализация объекта считается завершённой. При выходе из области видимости объекта происходит его деинициализация. Она сопровождается вызовом деструктора. Посмотрим, что происходит на этих этапах при выбрасывании исключения.</p>

<p>Иногда конструктор не может создать объект, находящийся в согласованном состоянии. Например, при попытке создать обыкновенную дробь с нулевым знаменателем. Если конструктор не может выполнить свою задачу, откажитесь от конструирования такого объекта, выбросив в конструкторе исключение. При этом нужно иметь в виду особенности, специфичные для языка C++.</p>

<p>Если во время работы конструктора выбрасывается исключение, инициализация объекта считается незавершённой. При этом деструктор такого объекта вызван не будет, что логично: объект фактически не создан. Зато будут вызваны деструкторы тех его полей, которые к этому моменту уже сконструированы. Рассмотрим на примере:</p>

<pre><code class="language-cpp">#include &lt;iostream&gt;
#include &lt;stdexcept&gt;
#include &lt;string&gt;

using namespace std;

class Greeter {
public:
    Greeter(const string&amp; name)
        : name_(name)  // Сохраняем name_ внутри
    {
        cout &lt;&lt; &quot;Hello, &quot;s &lt;&lt; name_ &lt;&lt; endl;
    }

    ~Greeter() {
        cout &lt;&lt; &quot;Goodbye, &quot;s &lt;&lt; name_ &lt;&lt; endl;
    }

private:
    string name_;
};

class Thrower {
public:
    Thrower()
        : field_(&quot;field&quot;s) // передаём параметры конструктору поля field_
    {
        cout &lt;&lt; &quot;Thrower()&quot;s &lt;&lt; endl;
        // Исключение, выброшенное здесь, будет поймано за пределами конструктора
        throw runtime_error(&quot;Oops&quot;s);
    }

    ~Thrower() {
        cout &lt;&lt; &quot;~Thrower()&quot;s &lt;&lt; endl;
    }

private:
    Greeter field_;
};

int main() {
    try {
        Thrower t;
    } catch (const runtime_error&amp; e) {
        cout &lt;&lt; e.what() &lt;&lt; endl;
    }
}
</code></pre>

<p>Программа выведет:</p>

<pre><code>Hello, field
Thrower()
Goodbye, field
Oops
</code></pre>

<p>Сначала будет сконструировано поле <code>field_</code> класса <code>Thrower</code>. Об этом говорит вывод <code>Hello, field</code>. Затем при выполнении тела конструктора <code>Thrower</code> будет выведена строка <code>Thrower()</code> и выброшено исключение, обработчик которого находится за пределами конструктора. В процессе раскрутки стека вызовется деструктор сконструированного поля <code>field_</code>, что подтверждает вывод строки <code>Goodbye, field</code>. А вот деструктор <code>Thrower</code> вызван не будет, так как конструирование объекта не было завершено.</p>

<h3>Выбрасывание исключения в деструкторе</h3>

<p>По умолчанию деструкторы в C++ не должны выбрасывать исключения. Если нарушить это правило, программа аварийно завершится. Такое ограничение обеспечивает корректную работу механизма раскрутки стека.</p>

<p>В коде ниже деструктор класса <code>ThrowsInDestructor</code> бросает исключение, которое в самом деструкторе никак не обрабатывается. В результате при выбрасывании исключения программа аварийно завершит работу:</p>

<pre><code class="language-cpp">#include &lt;iostream&gt;
#include &lt;stdexcept&gt;
#include &lt;string&gt;

using namespace std;

class ThrowsInDestructor {
public:
    ~ThrowsInDestructor() {
        cout &lt;&lt; &quot;See you&quot;s &lt;&lt; endl;
        throw runtime_error(&quot;Oops&quot;s);
    }
};

int main() {
    try {
        ThrowsInDestructor x;
    } catch (...) {
        // Этот код не будет вызван, так как выбрасывание исключения в деструкторе
        // класса ThrowsInDestructor приведёт к аварийному завершению работы программы
        cout &lt;&lt; &quot;Exception was caught&quot;s;
    }
}
</code></pre>

<p>Современные компиляторы умеют сообщать о таких проблемах предупреждением:</p>

<pre><code>warning: '~ThrowsInDestructor' has a non-throwing exception specification but can still throw [-Wexceptions]
        throw runtime_error(&quot;Oops&quot;s);
        ^
</code></pre>

<p>Если в деструкторе есть код, который может выбросить исключение, этот код помещают внутрь блока <code>try/catch</code>:</p>

<pre><code class="language-cpp">// Удаляет файл. В случае ошибки может выбросить исключение
void DeleteFile(const string&amp; path) {
    // ...
}

// Управляет временным файлом на диске. При своём разрушении удаляет временный файл
class TemporaryFile {
public:
    explicit TemporaryFile(const string&amp; path)
        : path_(path) {
    }

    const string&amp; GetPath() const {
        return path_;
    }

    ~TemporaryFile() {
        int retries = 10;
        while (retries &gt; 0) {
            try {
                DeleteFile(path_);
                break;
            } catch (...) {
                // Возможно, повезёт на следующей попытке,
                // если ошибка удаления файла была временной. 
                // Например, в момент удаления файл проверялся антивирусом 
                --retries;
            }
        }
    }

private:
    string path_;
};

int main() {
    // Для работы использует
    TemporaryFile tmpFile(&quot;temp.txt&quot;s);

    /* Что-нибудь делаем с этим файлом */

    // При выходе из функции деструктор TemporaryFile постарается удалить файл с диска
}
</code></pre>

<p>Раскрутка стека — полезный механизм, который за счёт детерминированного вызова деструкторов объектов освобождает ресурсы системы при возникновении исключительных ситуаций. Выбрасывание исключения в конструкторе — стандартный способ уведомить об ошибках, препятствующих созданию жизнеспособного объекта. А вот деструкторы выбрасывать исключений не должны.</p>

</body>
</html>
